<?xml version="1.0" ?>
<!-- =================================================================================== -->
<!-- |    This document was autogenerated by xacro from prius.urdf.xacro               | -->
<!-- |    EDITING THIS FILE BY HAND IS NOT RECOMMENDED                                 | -->
<!-- =================================================================================== -->
<robot name="prius_hybrid">
  <link name="chassis">
    <visual name="chassis_visual">
      <geometry>
        <mesh filename="package://prius_bringup/urdf/meshes/Hybrid.obj"/>
      </geometry>
    </visual>
    <origin>0 0 0 0 0 0</origin>
  </link>
  <link name="front_left_wheel">
    <origin>0.76000000000004775 -1.4099999999999682 0.30000000000000071 1.4745149545802863e-17 -8.6736173798840355e-18 -1.1102230246251568e-16</origin>
    <visual name="visual">
      <origin>0.040000000000000001 0 0 0 0 0</origin>
      <geometry>
        <sphere radius="0.31264999999999998"/>
      </geometry>
    </visual>
  </link>
  <link name="front_right_wheel">
    <origin>-0.75999999999994827 -1.410000000000025 0.30000000000000071 1.4745149545802863e-17 -8.6736173798840355e-18 -1.1102230246251568e-16</origin>
    <visual name="visual">
      <origin>-0.040000000000000001 0 0 0 0 0</origin>
      <geometry>
        <sphere radius="0.31264999999999998"/>
      </geometry>
    </visual>
  </link>
  <link name="rear_left_wheel">
    <origin>0.78600000000002979 1.4499999999999886 0.29999999999999893 1.4745149545802863e-17 -8.6736173798840355e-18 -1.1102230246251568e-16</origin>
    <visual name="visual">
      <origin>0.040000000000000001 0 0 0 0 0</origin>
      <geometry>
        <sphere radius="0.31264999999999998"/>
      </geometry>
    </visual>
  </link>
  <link name="rear_right_wheel">
    <origin>-0.78600000000002979 1.4499999999999886 0.29999999999999893 1.4745149545802863e-17 -8.6736173798840355e-18 -1.1102230246251568e-16</origin>
    <visual name="visual">
      <origin>-0.040000000000000001 0 0 0 0 0</origin>
      <geometry>
        <sphere radius="0.31264999999999998"/>
      </geometry>
    </visual>
  </link>
  <link name="rear_axle">
    <origin>-1.4210854715202004e-14 1.4499999999999318 0.30000000000000071 3.4694469519536142e-18 -3.4694469519536142e-18 -1.1102230246251565e-16</origin>
    <visual name="visual">
      <origin>0 0 0 0 1.5707963267948966 0</origin>
      <geometry>
        <cylinder length="1.357" radius="0.074999999999999997"/>
      </geometry>
    </visual>
  </link>
  <joint name="rear_axle_joint" type="revolute">
    <child>rear_axle</child>
    <parent>chassis</parent>
    <axis xyz="0 1 0"/>
    <limit effort="100" lower="-0.050890585241730277" upper="0.050890585241730277" velocity="1.0"/>
    <origin>0 0 0 0 0 0</origin>
  </joint>
  <joint name="rear_left_wheel_joint" type="continuous">
    <parent>rear_axle</parent>
    <child>rear_left_wheel</child>
    <origin rpy="0 0 0" xyz="0 0 0"/>
    <axis xyz="1 0 0"/>
    <limit effort="1000000" lower="-1000.0" upper="1000.0" velocity="100.0"/>
  </joint>
  <joint name="rear_right_wheel_joint" type="continuous">
    <parent>rear_axle</parent>
    <child>rear_right_wheel</child>
    <origin rpy="0 0 0" xyz="0 0 0"/>
    <axis xyz="1 0 0"/>
    <limit effort="1000000" lower="-1000.0" upper="1000.0" velocity="100.0"/>
  </joint>
  <link name="front_left_wheel_steering_link">
    <visual>
      <geometry>
        <box size="0.1 0.1 0.1"/>
      </geometry>
    </visual>
  </link>
  <link name="front_right_wheel_steering_link">
    <visual>
      <geometry>
        <box size="0.1 0.1 0.1"/>
      </geometry>
    </visual>
  </link>
  <joint name="front_left_wheel_steering_joint" type="revolute">
    <parent>chassis</parent>
    <child>front_left_wheel_steering_link</child>
    <origin rpy="0 0 0" xyz="0 0 0"/>
    <axis xyz="0 0 1"/>
    <limit effort="1000000" lower="-0.8727" upper="0.8727" velocity="10.0"/>
  </joint>
  <joint name="front_right_wheel_steering_joint" type="revolute">
    <parent>chassis</parent>
    <child>front_right_wheel_steering_link</child>
    <origin rpy="0 0 0" xyz="0 0 0"/>
    <axis xyz="0 0 1"/>
    <limit effort="1000000" lower="-0.8727" upper="0.8727" velocity="10.0"/>
  </joint>
  <joint name="front_left_wheel_joint" type="continuous">
    <parent>front_left_wheel_steering_link</parent>
    <child>front_left_wheel</child>
    <origin rpy="0 0 0" xyz="0 0 0"/>
    <axis xyz="1 0 0"/>
    <limit effort="1000000" lower="-1000.0" upper="1000.0" velocity="100.0"/>
  </joint>
  <joint name="front_right_wheel_joint" type="continuous">
    <parent>front_right_wheel_steering_link</parent>
    <child>front_right_wheel</child>
    <origin rpy="0 0 0" xyz="0 0 0"/>
    <axis xyz="1 0 0"/>
    <limit effort="1000000" lower="-1000.0" upper="1000.0" velocity="100.0"/>
  </joint>
</robot>
