<?xml version="1.0" ?>
<sdf version="1.6">
  <model name='prius_hybrid'>
    <link name='chassis'>
      <inertial>
        <mass>1326</mass>
        <pose>0 -0.26600000000000001 0.47999999999999998 0 0 0</pose>
        <inertia>
          <ixx>2581.1335474000002</ixx>
          <ixy>0</ixy>
          <iyy>591.30846111999995</iyy>
          <ixz>0</ixz>
          <iyz>0</iyz>
          <izz>2681.9500862800001</izz>
        </inertia>
      </inertial>
      <visual name='chassis_visual'>
        <geometry>
          <mesh>
            <uri>https://fuel.ignitionrobotics.org/1.0/openrobotics/models/prius hybrid/2/files/meshes/Hybrid.obj</uri>
            <scale>0.01 0.01 0.01</scale>
            <submesh>
              <name>Hybrid</name>
              <center>false</center>
            </submesh>
          </mesh>
        </geometry>
      </visual>
      <visual name='interior_visual'>
        <geometry>
          <mesh>
            <uri>https://fuel.ignitionrobotics.org/1.0/openrobotics/models/prius hybrid/2/files/meshes/Hybrid.obj</uri>
            <scale>0.01 0.01 0.01</scale>
            <submesh>
              <name>Hybrid_Interior</name>
              <center>false</center>
            </submesh>
          </mesh>
        </geometry>
      </visual>
      <visual name='windows_visual'>
        <geometry>
          <mesh>
            <uri>https://fuel.ignitionrobotics.org/1.0/openrobotics/models/prius hybrid/2/files/meshes/Hybrid.obj</uri>
            <scale>0.01 0.01 0.01</scale>
            <submesh>
              <name>Hybrid_Windows</name>
              <center>false</center>
            </submesh>
          </mesh>
        </geometry>
      </visual>
      <collision name='chassis'>
        <pose>0 0.050000000000000003 0.625 0 0 0</pose>
        <geometry>
          <box>
            <size>1.7525999999999999 2.1000000000000001 0.94999999999999996</size>
          </box>
        </geometry>
        <surface>
          <friction>
            <ode/>
          </friction>
          <bounce/>
          <contact/>
        </surface>
      </collision>
      <collision name='front_bumper'>
        <pose>0 -2 0.45848800000000001 0 0 0</pose>
        <geometry>
          <box>
            <size>1.3372820000000001 0.47999999999999998 0.56669099999999994</size>
          </box>
        </geometry>
        <surface>
          <friction>
            <ode/>
          </friction>
          <bounce/>
          <contact/>
        </surface>
      </collision>
      <collision name='hood'>
        <pose>0 -1.9008419999999999 0.67630500000000005 0.34124700000000008 0 0</pose>
        <geometry>
          <box>
            <size>1.5979680000000001 0.49310700000000002 0.26546799999999998</size>
          </box>
        </geometry>
        <surface>
          <friction>
            <ode/>
          </friction>
          <bounce/>
          <contact/>
        </surface>
      </collision>
      <collision name='windshield'>
        <pose>0 -0.87510500000000002 1.032268 0.335476 0 0</pose>
        <geometry>
          <box>
            <size>1.1683809999999999 1.654253 0.27234700000000001</size>
          </box>
        </geometry>
        <surface>
          <friction>
            <ode/>
          </friction>
          <bounce/>
          <contact/>
        </surface>
      </collision>
      <collision name='top_front'>
        <pose>0 0.16123599999999999 1.386042 0.13503000000000004 0 0</pose>
        <geometry>
          <box>
            <size>1.2791539999999999 0.62598799999999999 0.17186799999999999</size>
          </box>
        </geometry>
        <surface>
          <friction>
            <ode/>
          </friction>
          <bounce/>
          <contact/>
        </surface>
      </collision>
      <collision name='top_rear'>
        <pose>0 0.81769599999999998 1.360069 -0.068997000000000003 0 0</pose>
        <geometry>
          <box>
            <size>1.2851300000000001 0.77118900000000001 0.22655700000000001</size>
          </box>
        </geometry>
        <surface>
          <friction>
            <ode/>
          </friction>
          <bounce/>
          <contact/>
        </surface>
      </collision>
      <collision name='rear_window'>
        <pose>0 1.640531 1.1751259999999999 -0.26201699999999994 0 0</pose>
        <geometry>
          <box>
            <size>1.2678450000000001 1.116344 0.244286</size>
          </box>
        </geometry>
        <surface>
          <friction>
            <ode/>
          </friction>
          <bounce/>
          <contact/>
        </surface>
      </collision>
      <collision name='trunk'>
        <pose>0 1.637059 0.88817999999999997 0 0 0</pose>
        <geometry>
          <box>
            <size>1.7880640000000001 1.1389879999999999 0.48274600000000001</size>
          </box>
        </geometry>
        <surface>
          <friction>
            <ode/>
          </friction>
          <bounce/>
          <contact/>
        </surface>
      </collision>
      <collision name='back_bumper'>
        <pose>0 2.0544539999999998 0.57786999999999999 0 0 0</pose>
        <geometry>
          <box>
            <size>1.78165 0.51209300000000002 0.58142700000000003</size>
          </box>
        </geometry>
        <surface>
          <friction>
            <ode/>
          </friction>
          <bounce/>
          <contact/>
        </surface>
      </collision>
      <pose>0 0 0 0 0 0</pose>
      <enable_wind>false</enable_wind>
    </link>
    <link name='steering_wheel'>
      <pose>0.35773399999999356 -0.62786799999997811 0.98824299999999887 -1.3021010000000002 -1.8081556470492215e-16 -4.205316985790385e-16</pose>
      <inertial>
        <mass>1</mass>
        <inertia>
          <ixx>0.14583299999999999</ixx>
          <ixy>0</ixy>
          <ixz>0</ixz>
          <iyy>0.14583299999999999</iyy>
          <iyz>0</iyz>
          <izz>0.125</izz>
        </inertia>
        <pose>0 0 0 0 0 0</pose>
      </inertial>
      <collision name='collision'>
        <geometry>
          <cylinder>
            <radius>0.178172</radius>
            <length>0.041845</length>
          </cylinder>
        </geometry>
        <surface>
          <contact>
            <ode>
              <min_depth>0.0030000000000000001</min_depth>
            </ode>
          </contact>
          <friction>
            <ode/>
          </friction>
          <bounce/>
        </surface>
      </collision>
      <visual name='visual'>
        <pose>0 0 0 1.302101 0 0</pose>
        <geometry>
          <mesh>
            <uri>https://fuel.ignitionrobotics.org/1.0/openrobotics/models/prius hybrid/2/files/meshes/Hybrid.obj</uri>
            <scale>0.01 0.01 0.01</scale>
            <submesh>
              <name>Steering_Wheel</name>
              <center>true</center>
            </submesh>
          </mesh>
        </geometry>
      </visual>
      <enable_wind>false</enable_wind>
    </link>
    <link name='front_left_wheel'>
      <pose>0.76000000000004775 -1.4099999999999682 0.30000000000000071 1.4745149545802863e-17 -8.6736173798840355e-18 -1.1102230246251568e-16</pose>
      <inertial>
        <mass>11</mass>
        <inertia>
          <ixx>0.58631237999999997</ixx>
          <ixy>0</ixy>
          <iyy>0.33552910000000002</iyy>
          <ixz>0</ixz>
          <iyz>0</iyz>
          <izz>0.33552910000000002</izz>
        </inertia>
        <pose>0 0 0 0 0 0</pose>
      </inertial>
      <visual name='visual'>
        <pose>0.040000000000000001 0 0 0 0 0</pose>
        <geometry>
          <mesh>
            <uri>https://fuel.ignitionrobotics.org/1.0/openrobotics/models/prius hybrid/2/files/meshes/Hybrid.obj</uri>
            <scale>0.01 0.01 0.01</scale>
            <submesh>
              <name>Wheel_Front_Left_</name>
              <center>true</center>
            </submesh>
          </mesh>
        </geometry>
      </visual>
      <collision name='collision'>
        <pose>0 0 0 0 1.5707963267948966 0</pose>
        <geometry>
          <sphere>
            <radius>0.31265</radius>
          </sphere>
        </geometry>
        <surface>
          <friction>
            <ode>
              <mu>0.90000000000000002</mu>
              <mu2>0.90000000000000002</mu2>
              <slip1>0</slip1>
              <slip2>0</slip2>
            </ode>
          </friction>
          <contact>
            <ode>
              <min_depth>0.001</min_depth>
              <kp>1000000000</kp>
            </ode>
          </contact>
          <bounce/>
        </surface>
      </collision>
      <enable_wind>false</enable_wind>
    </link>
    <link name='front_right_wheel'>
      <pose>-0.75999999999994827 -1.410000000000025 0.30000000000000071 1.4745149545802863e-17 -8.6736173798840355e-18 -1.1102230246251568e-16</pose>
      <inertial>
        <mass>11</mass>
        <inertia>
          <ixx>0.58631237999999997</ixx>
          <ixy>0</ixy>
          <iyy>0.33552910000000002</iyy>
          <ixz>0</ixz>
          <iyz>0</iyz>
          <izz>0.33552910000000002</izz>
        </inertia>
        <pose>0 0 0 0 0 0</pose>
      </inertial>
      <visual name='visual'>
        <pose>-0.040000000000000001 0 0 0 0 0</pose>
        <pose>0 0 0 0 0 0</pose>
        <geometry>
          <mesh>
            <uri>https://fuel.ignitionrobotics.org/1.0/openrobotics/models/prius hybrid/2/files/meshes/Hybrid.obj</uri>
            <scale>0.01 0.01 0.01</scale>
            <submesh>
              <name>Wheel_Front_Right</name>
              <center>true</center>
            </submesh>
          </mesh>
        </geometry>
      </visual>
      <collision name='collision'>
        <pose>0 0 0 0 1.5707963267948966 0</pose>
        <geometry>
          <sphere>
            <radius>0.31265</radius>
          </sphere>
        </geometry>
        <surface>
          <friction>
            <ode>
              <mu>0.90000000000000002</mu>
              <mu2>0.90000000000000002</mu2>
              <slip1>0</slip1>
              <slip2>0</slip2>
            </ode>
          </friction>
          <contact>
            <ode>
              <min_depth>0.001</min_depth>
              <kp>1000000000</kp>
            </ode>
          </contact>
          <bounce/>
        </surface>
      </collision>
      <enable_wind>false</enable_wind>
    </link>
    <link name='rear_left_wheel'>
      <pose>0.78600000000002979 1.4499999999999886 0.29999999999999893 1.4745149545802863e-17 -8.6736173798840355e-18 -1.1102230246251568e-16</pose>
      <inertial>
        <mass>11</mass>
        <inertia>
          <ixx>0.58631237999999997</ixx>
          <ixy>0</ixy>
          <iyy>0.33552910000000002</iyy>
          <ixz>0</ixz>
          <iyz>0</iyz>
          <izz>0.33552910000000002</izz>
        </inertia>
        <pose>0 0 0 0 0 0</pose>
      </inertial>
      <visual name='visual'>
        <pose>0.040000000000000001 0 0 0 0 0</pose>
        <geometry>
          <mesh>
            <uri>https://fuel.ignitionrobotics.org/1.0/openrobotics/models/prius hybrid/2/files/meshes/Hybrid.obj</uri>
            <scale>0.01 0.01 0.01</scale>
            <submesh>
              <name>Wheel_Front_Left_</name>
              <center>true</center>
            </submesh>
          </mesh>
        </geometry>
      </visual>
      <collision name='collision'>
        <pose>0 0 0 0 1.5707963267948966 0</pose>
        <geometry>
          <sphere>
            <radius>0.31264999999999998</radius>
          </sphere>
        </geometry>
        <surface>
          <friction>
            <ode>
              <mu>1.1000000000000001</mu>
              <mu2>1.1000000000000001</mu2>
              <slip1>0</slip1>
              <slip2>0</slip2>
            </ode>
          </friction>
          <contact>
            <ode>
              <min_depth>0.001</min_depth>
              <kp>1000000000</kp>
            </ode>
          </contact>
          <bounce/>
        </surface>
      </collision>
      <enable_wind>false</enable_wind>
    </link>
    <link name='rear_right_wheel'>
      <pose>-0.78600000000002979 1.4499999999999886 0.29999999999999893 1.4745149545802863e-17 -8.6736173798840355e-18 -1.1102230246251568e-16</pose>
      <inertial>
        <mass>11</mass>
        <inertia>
          <ixx>0.58631237999999997</ixx>
          <ixy>0</ixy>
          <iyy>0.33552910000000002</iyy>
          <ixz>0</ixz>
          <iyz>0</iyz>
          <izz>0.33552910000000002</izz>
        </inertia>
        <pose>0 0 0 0 0 0</pose>
      </inertial>
      <visual name='visual'>
        <pose>-0.040000000000000001 0 0 0 0 0</pose>
        <geometry>
          <mesh>
            <uri>https://fuel.ignitionrobotics.org/1.0/openrobotics/models/prius hybrid/2/files/meshes/Hybrid.obj</uri>
            <scale>0.01 0.01 0.01</scale>
            <submesh>
              <name>Wheel_Front_Right</name>
              <center>true</center>
            </submesh>
          </mesh>
        </geometry>
      </visual>
      <collision name='collision'>
        <pose>0 0 0 0 1.5707963267948966 0</pose>
        <geometry>
          <sphere>
            <radius>0.31264999999999998</radius>
          </sphere>
        </geometry>
        <surface>
          <friction>
            <ode>
              <mu>1.1000000000000001</mu>
              <mu2>1.1000000000000001</mu2>
              <slip1>0</slip1>
              <slip2>0</slip2>
            </ode>
          </friction>
          <contact>
            <ode>
              <min_depth>0.001</min_depth>
              <kp>1000000000</kp>
            </ode>
          </contact>
          <bounce/>
        </surface>
      </collision>
      <enable_wind>false</enable_wind>
    </link>
    <link name='rear_axle'>
      <pose>-1.4210854715202004e-14 1.4499999999999318 0.30000000000000071 3.4694469519536142e-18 -3.4694469519536142e-18 -1.1102230246251565e-16</pose>
      <inertial>
        <mass>30</mass>
        <inertia>
          <ixx>0.084374999999999992</ixx>
          <ixy>0</ixy>
          <iyy>4.64581</iyy>
          <ixz>0</ixz>
          <iyz>0</iyz>
          <izz>4.64581</izz>
        </inertia>
        <pose>0 0 0 0 0 0</pose>
      </inertial>
      <visual name='visual'>
        <pose>0 0 0 0 1.5707963267948966 0</pose>
        <geometry>
          <cylinder>
            <length>1.357</length>
            <radius>0.074999999999999997</radius>
          </cylinder>
        </geometry>
        <material>
          <script>
            <name>Gazebo/Grey</name>
            <uri>file://media/materials/scripts/gazebo.material</uri>
          </script>
        </material>
      </visual>
      <enable_wind>false</enable_wind>
    </link>
    <joint name='rear_axle_joint' type='revolute'>
      <child>rear_axle</child>
      <parent>chassis</parent>
      <axis>
        <xyz>0 1 0</xyz>
        <limit>
          <lower>-0.050890585241730277</lower>
          <upper>0.050890585241730277</upper>
          <effort>inf</effort>
          <velocity>inf</velocity>
          <stiffness>100000000</stiffness>
          <dissipation>1</dissipation>
        </limit>
        <dynamics>
          <spring_reference>0</spring_reference>
          <spring_stiffness>20000</spring_stiffness>
          <damping>2000</damping>
          <friction>0</friction>
        </dynamics>
      </axis>
      <pose>0 0 0 0 0 0</pose>
    </joint>
    <joint name='rear_left_wheel_joint' type='revolute'>
      <child>rear_left_wheel</child>
      <parent>rear_axle</parent>
      <axis>
        <xyz>1 0 0</xyz>
        <limit>
          <lower>-inf</lower>
          <upper>inf</upper>
          <effort>inf</effort>
          <velocity>inf</velocity>
          <stiffness>100000000</stiffness>
          <dissipation>1</dissipation>
        </limit>
        <dynamics>
          <spring_reference>0</spring_reference>
          <spring_stiffness>0</spring_stiffness>
          <damping>0</damping>
          <friction>12.031606150200002</friction>
        </dynamics>
      </axis>
      <pose>0 0 0 0 0 0</pose>
    </joint>
    <joint name='rear_right_wheel_joint' type='revolute'>
      <child>rear_right_wheel</child>
      <parent>rear_axle</parent>
      <axis>
        <xyz>1 0 0</xyz>
        <limit>
          <lower>-inf</lower>
          <upper>inf</upper>
          <effort>inf</effort>
          <velocity>inf</velocity>
          <stiffness>100000000</stiffness>
          <dissipation>1</dissipation>
        </limit>
        <dynamics>
          <spring_reference>0</spring_reference>
          <spring_stiffness>0</spring_stiffness>
          <damping>0</damping>
          <friction>12.031606150200002</friction>
        </dynamics>
      </axis>
      <pose>0 0 0 0 0 0</pose>
    </joint>
    <joint name='steering_joint' type='revolute'>
      <pose>-0.0020000000000000018 -2.2204460492503131e-16 1.1102230246251565e-16 0 0 0</pose>
      <parent>chassis</parent>
      <child>steering_wheel</child>
      <axis>
        <xyz>0 0.96409540580664155 0.26555611177776933</xyz>
        <limit>
          <lower>-7.8499999999999996</lower>
          <upper>7.8499999999999996</upper>
          <effort>inf</effort>
          <velocity>inf</velocity>
          <stiffness>100000000</stiffness>
          <dissipation>1</dissipation>
        </limit>
        <dynamics>
          <spring_reference>0</spring_reference>
          <spring_stiffness>0</spring_stiffness>
          <damping>1</damping>
          <friction>0</friction>
        </dynamics>
      </axis>
      <physics>
        <ode>
          <cfm_damping>true</cfm_damping>
        </ode>
      </physics>
    </joint>
    <link name='front_left_wheel_steering_link'>
      <pose>0.76000000000004775 -1.4099999999999682 0.30000000000000071 3.4694469519536142e-18 -3.4694469519536142e-18 -1.1102230246251565e-16</pose>
      <inertial>
        <mass>0.5</mass>
        <inertia>
          <ixx>0.015299999999999999</ixx>
          <iyy>0.025000000000000001</iyy>
          <izz>0.015299999999999999</izz>
          <ixy>0</ixy>
          <ixz>0</ixz>
          <iyz>0</iyz>
        </inertia>
        <pose>0 0 0 0 0 0</pose>
      </inertial>
      <enable_wind>false</enable_wind>
    </link>
    <link name='front_right_wheel_steering_link'>
      <pose>-0.75999999999994827 -1.410000000000025 0.30000000000000071 3.4694469519536142e-18 -3.4694469519536142e-18 -1.1102230246251565e-16</pose>
      <inertial>
        <mass>0.5</mass>
        <inertia>
          <ixx>0.015299999999999999</ixx>
          <iyy>0.025000000000000001</iyy>
          <izz>0.015299999999999999</izz>
          <ixy>0</ixy>
          <ixz>0</ixz>
          <iyz>0</iyz>
        </inertia>
        <pose>0 0 0 0 0 0</pose>
      </inertial>
      <enable_wind>false</enable_wind>
    </link>
    <joint name='front_left_wheel_steering_joint' type='revolute'>
      <child>front_left_wheel_steering_link</child>
      <parent>chassis</parent>
      <axis>
        <xyz>0 0 1</xyz>
        <limit>
          <lower>-0.87270000000000003</lower>
          <upper>0.87270000000000003</upper>
          <effort>1000000</effort>
          <velocity>inf</velocity>
          <stiffness>100000000</stiffness>
          <dissipation>1</dissipation>
        </limit>
        <dynamics>
          <spring_reference>0</spring_reference>
          <spring_stiffness>0</spring_stiffness>
          <damping>0</damping>
          <friction>0</friction>
        </dynamics>
      </axis>
      <pose>0 0 0 0 0 0</pose>
    </joint>
    <joint name='front_right_wheel_steering_joint' type='revolute'>
      <parent>chassis</parent>
      <child>front_right_wheel_steering_link</child>
      <axis>
        <xyz>0 0 1</xyz>
        <limit>
          <lower>-0.87270000000000003</lower>
          <upper>0.87270000000000003</upper>
          <effort>1000000</effort>
          <velocity>inf</velocity>
          <stiffness>100000000</stiffness>
          <dissipation>1</dissipation>
        </limit>
        <dynamics>
          <spring_reference>0</spring_reference>
          <spring_stiffness>0</spring_stiffness>
          <damping>0</damping>
          <friction>0</friction>
        </dynamics>
      </axis>
      <pose>0 0 0 0 0 0</pose>
    </joint>
    <joint name='front_left_wheel_joint' type='revolute'>
      <parent>front_left_wheel_steering_link</parent>
      <child>front_left_wheel</child>
      <axis>
        <xyz>1 0 0</xyz>
        <limit>
          <lower>-1.7976900000000001e+308</lower>
          <upper>1.7976900000000001e+308</upper>
          <effort>inf</effort>
          <velocity>inf</velocity>
          <stiffness>100000000</stiffness>
          <dissipation>1</dissipation>
        </limit>
        <dynamics>
          <spring_reference>0</spring_reference>
          <spring_stiffness>0</spring_stiffness>
          <damping>0</damping>
          <friction>18.047409225300001</friction>
        </dynamics>
      </axis>
      <pose>0 0 0 0 0 0</pose>
    </joint>
    <joint name='front_right_wheel_joint' type='revolute'>
      <parent>front_right_wheel_steering_link</parent>
      <child>front_right_wheel</child>
      <axis>
        <xyz>1 0 0</xyz>
        <limit>
          <lower>-1.7976900000000001e+308</lower>
          <upper>1.7976900000000001e+308</upper>
          <effort>inf</effort>
          <velocity>inf</velocity>
          <stiffness>100000000</stiffness>
          <dissipation>1</dissipation>
        </limit>
        <dynamics>
          <spring_reference>0</spring_reference>
          <spring_stiffness>0</spring_stiffness>
          <damping>0</damping>
          <friction>18.047409225300001</friction>
        </dynamics>
      </axis>
      <pose>0 0 0 0 0 0</pose>
    </joint>
    <plugin name='ignition::gazebo::systems::AckermannSteering' filename='ignition-gazebo-ackermann-steering-system'>
      <frame_id>odom</frame_id>
      <child_frame_id>chassis</child_frame_id>
      <topic>/prius_hybrid/cmd_vel</topic>
      <tf_topic>/prius_hybrid/tf</tf_topic>
      <odom_topic>/prius_hybrid/steering_odom</odom_topic>
      <left_joint>front_left_wheel_joint</left_joint>
      <left_joint>rear_left_wheel_joint</left_joint>
      <right_joint>front_right_wheel_joint</right_joint>
      <right_joint>rear_right_wheel_joint</right_joint>
      <left_steering_joint>front_left_wheel_steering_joint</left_steering_joint>
      <right_steering_joint>front_right_wheel_steering_joint</right_steering_joint>
      <kingpin_width>1.0</kingpin_width>
      <steering_limit>0.5</steering_limit>
      <wheel_base>1.0</wheel_base>
      <wheel_separation>1.572</wheel_separation>
      <wheel_radius>0.31265</wheel_radius>
      <min_velocity>-10</min_velocity>
      <max_velocity>100</max_velocity>
      <min_acceleration>-30</min_acceleration>
      <max_acceleration>30</max_acceleration>
    </plugin>
    <static>false</static>
    <self_collide>false</self_collide>
  </model>

</sdf>
